{
 "cells": [
  {
   "cell_type": "markdown",
   "metadata": {},
   "source": [
    "___\n",
    "\n",
    "<a href='http://www.pieriandata.com'> <img src='../Pierian_Data_Logo.png' /></a>\n",
    "___"
   ]
  },
  {
   "cell_type": "markdown",
   "metadata": {},
   "source": [
    "# Tensorflow with Estimators\n",
    "\n",
    "As we saw previously how to build a full Multi-Layer Perceptron model with full Sessions in Tensorflow. Unfortunately this was an extremely involved process. However developers have created Estimators that have an easier to use flow!\n",
    "\n",
    "It is much easier to use, but you sacrifice some level of customization of your model. Let's go ahead and explore it!"
   ]
  },
  {
   "cell_type": "markdown",
   "metadata": {},
   "source": [
    "## Get the Data\n",
    "\n",
    "We will the iris data set.\n",
    "\n",
    "Let's get the data:"
   ]
  },
  {
   "cell_type": "code",
   "execution_count": 12,
   "metadata": {},
   "outputs": [
    {
     "name": "stdout",
     "output_type": "stream",
     "text": [
      "ERROR! Session/line number was not unique in database. History logging moved to new session 855\n"
     ]
    }
   ],
   "source": [
    "import pandas as pd\n",
    "import numpy as np\n",
    "import matplotlib.pyplot as plt\n",
    "import seaborn as sns\n",
    "%matplotlib inline"
   ]
  },
  {
   "cell_type": "code",
   "execution_count": null,
   "metadata": {},
   "outputs": [
    {
     "name": "stderr",
     "output_type": "stream",
     "text": [
      "ERROR:root:Internal Python error in the inspect module.\n",
      "Below is the traceback from this internal error.\n",
      "\n",
      "ERROR:root:Internal Python error in the inspect module.\n",
      "Below is the traceback from this internal error.\n",
      "\n",
      "ERROR:root:Internal Python error in the inspect module.\n",
      "Below is the traceback from this internal error.\n",
      "\n"
     ]
    },
    {
     "name": "stdout",
     "output_type": "stream",
     "text": [
      "Traceback (most recent call last):\n",
      "  File \"D:\\anaconda\\lib\\site-packages\\IPython\\core\\interactiveshell.py\", line 3417, in run_code\n",
      "    exec(code_obj, self.user_global_ns, self.user_ns)\n",
      "  File \"<ipython-input-13-4b54e0986ec4>\", line 1, in <module>\n",
      "    loans = pd.read_csv('loan_data.csv')\n",
      "  File \"D:\\anaconda\\lib\\site-packages\\pandas\\io\\parsers.py\", line 686, in read_csv\n",
      "    return _read(filepath_or_buffer, kwds)\n",
      "  File \"D:\\anaconda\\lib\\site-packages\\pandas\\io\\parsers.py\", line 452, in _read\n",
      "    parser = TextFileReader(fp_or_buf, **kwds)\n",
      "  File \"D:\\anaconda\\lib\\site-packages\\pandas\\io\\parsers.py\", line 936, in __init__\n",
      "    self._make_engine(self.engine)\n",
      "  File \"D:\\anaconda\\lib\\site-packages\\pandas\\io\\parsers.py\", line 1168, in _make_engine\n",
      "    self._engine = CParserWrapper(self.f, **self.options)\n",
      "  File \"D:\\anaconda\\lib\\site-packages\\pandas\\io\\parsers.py\", line 1998, in __init__\n",
      "    self._reader = parsers.TextReader(src, **kwds)\n",
      "  File \"pandas\\_libs\\parsers.pyx\", line 361, in pandas._libs.parsers.TextReader.__cinit__\n",
      "  File \"pandas\\_libs\\parsers.pyx\", line 653, in pandas._libs.parsers.TextReader._setup_parser_source\n",
      "FileNotFoundError: [Errno 2] No such file or directory: 'loan_data.csv'\n",
      "\n",
      "During handling of the above exception, another exception occurred:\n",
      "\n",
      "Traceback (most recent call last):\n",
      "  File \"D:\\anaconda\\lib\\site-packages\\IPython\\core\\interactiveshell.py\", line 2044, in showtraceback\n",
      "    stb = value._render_traceback_()\n",
      "AttributeError: 'FileNotFoundError' object has no attribute '_render_traceback_'\n",
      "\n",
      "During handling of the above exception, another exception occurred:\n",
      "\n",
      "Traceback (most recent call last):\n",
      "  File \"D:\\anaconda\\lib\\site-packages\\IPython\\core\\ultratb.py\", line 1169, in get_records\n",
      "    return _fixed_getinnerframes(etb, number_of_lines_of_context, tb_offset)\n",
      "  File \"D:\\anaconda\\lib\\site-packages\\IPython\\core\\ultratb.py\", line 316, in wrapped\n",
      "    return f(*args, **kwargs)\n",
      "  File \"D:\\anaconda\\lib\\site-packages\\IPython\\core\\ultratb.py\", line 350, in _fixed_getinnerframes\n",
      "    records = fix_frame_records_filenames(inspect.getinnerframes(etb, context))\n",
      "  File \"D:\\anaconda\\lib\\inspect.py\", line 1502, in getinnerframes\n",
      "    frameinfo = (tb.tb_frame,) + getframeinfo(tb, context)\n",
      "  File \"D:\\anaconda\\lib\\inspect.py\", line 1460, in getframeinfo\n",
      "    filename = getsourcefile(frame) or getfile(frame)\n",
      "  File \"D:\\anaconda\\lib\\inspect.py\", line 696, in getsourcefile\n",
      "    if getattr(getmodule(object, filename), '__loader__', None) is not None:\n",
      "  File \"D:\\anaconda\\lib\\inspect.py\", line 733, in getmodule\n",
      "    if ismodule(module) and hasattr(module, '__file__'):\n",
      "  File \"D:\\anaconda\\lib\\site-packages\\tensorflow\\__init__.py\", line 50, in __getattr__\n",
      "    module = self._load()\n",
      "  File \"D:\\anaconda\\lib\\site-packages\\tensorflow\\__init__.py\", line 44, in _load\n",
      "    module = _importlib.import_module(self.__name__)\n",
      "  File \"D:\\anaconda\\lib\\importlib\\__init__.py\", line 127, in import_module\n",
      "    return _bootstrap._gcd_import(name[level:], package, level)\n",
      "  File \"<frozen importlib._bootstrap>\", line 1006, in _gcd_import\n",
      "  File \"<frozen importlib._bootstrap>\", line 983, in _find_and_load\n",
      "  File \"<frozen importlib._bootstrap>\", line 965, in _find_and_load_unlocked\n",
      "ModuleNotFoundError: No module named 'tensorflow_core.estimator'\n",
      "ERROR! Session/line number was not unique in database. History logging moved to new session 856\n",
      "Traceback (most recent call last):\n",
      "  File \"D:\\anaconda\\lib\\site-packages\\IPython\\core\\interactiveshell.py\", line 3417, in run_code\n",
      "    exec(code_obj, self.user_global_ns, self.user_ns)\n",
      "  File \"<ipython-input-13-4b54e0986ec4>\", line 1, in <module>\n",
      "    loans = pd.read_csv('loan_data.csv')\n",
      "  File \"D:\\anaconda\\lib\\site-packages\\pandas\\io\\parsers.py\", line 686, in read_csv\n",
      "    return _read(filepath_or_buffer, kwds)\n",
      "  File \"D:\\anaconda\\lib\\site-packages\\pandas\\io\\parsers.py\", line 452, in _read\n",
      "    parser = TextFileReader(fp_or_buf, **kwds)\n",
      "  File \"D:\\anaconda\\lib\\site-packages\\pandas\\io\\parsers.py\", line 936, in __init__\n",
      "    self._make_engine(self.engine)\n",
      "  File \"D:\\anaconda\\lib\\site-packages\\pandas\\io\\parsers.py\", line 1168, in _make_engine\n",
      "    self._engine = CParserWrapper(self.f, **self.options)\n",
      "  File \"D:\\anaconda\\lib\\site-packages\\pandas\\io\\parsers.py\", line 1998, in __init__\n",
      "    self._reader = parsers.TextReader(src, **kwds)\n",
      "  File \"pandas\\_libs\\parsers.pyx\", line 361, in pandas._libs.parsers.TextReader.__cinit__\n",
      "  File \"pandas\\_libs\\parsers.pyx\", line 653, in pandas._libs.parsers.TextReader._setup_parser_source\n",
      "FileNotFoundError: [Errno 2] No such file or directory: 'loan_data.csv'\n",
      "\n",
      "During handling of the above exception, another exception occurred:\n",
      "\n",
      "Traceback (most recent call last):\n",
      "  File \"D:\\anaconda\\lib\\site-packages\\IPython\\core\\interactiveshell.py\", line 2044, in showtraceback\n",
      "    stb = value._render_traceback_()\n",
      "AttributeError: 'FileNotFoundError' object has no attribute '_render_traceback_'\n",
      "\n",
      "During handling of the above exception, another exception occurred:\n",
      "\n",
      "Traceback (most recent call last):\n",
      "  File \"D:\\anaconda\\lib\\site-packages\\IPython\\core\\interactiveshell.py\", line 3337, in run_ast_nodes\n",
      "    if (await self.run_code(code, result,  async_=asy)):\n",
      "  File \"D:\\anaconda\\lib\\site-packages\\IPython\\core\\interactiveshell.py\", line 3434, in run_code\n",
      "    self.showtraceback(running_compiled_code=True)\n",
      "  File \"D:\\anaconda\\lib\\site-packages\\IPython\\core\\interactiveshell.py\", line 2047, in showtraceback\n",
      "    value, tb, tb_offset=tb_offset)\n",
      "  File \"D:\\anaconda\\lib\\site-packages\\IPython\\core\\ultratb.py\", line 1436, in structured_traceback\n",
      "    self, etype, value, tb, tb_offset, number_of_lines_of_context)\n",
      "  File \"D:\\anaconda\\lib\\site-packages\\IPython\\core\\ultratb.py\", line 1336, in structured_traceback\n",
      "    self, etype, value, tb, tb_offset, number_of_lines_of_context\n",
      "  File \"D:\\anaconda\\lib\\site-packages\\IPython\\core\\ultratb.py\", line 1193, in structured_traceback\n",
      "    tb_offset)\n",
      "  File \"D:\\anaconda\\lib\\site-packages\\IPython\\core\\ultratb.py\", line 1150, in format_exception_as_a_whole\n",
      "    last_unique, recursion_repeat = find_recursion(orig_etype, evalue, records)\n",
      "  File \"D:\\anaconda\\lib\\site-packages\\IPython\\core\\ultratb.py\", line 451, in find_recursion\n",
      "    return len(records), 0\n",
      "TypeError: object of type 'NoneType' has no len()\n",
      "\n",
      "During handling of the above exception, another exception occurred:\n",
      "\n",
      "Traceback (most recent call last):\n",
      "  File \"D:\\anaconda\\lib\\site-packages\\IPython\\core\\interactiveshell.py\", line 2044, in showtraceback\n",
      "    stb = value._render_traceback_()\n",
      "AttributeError: 'TypeError' object has no attribute '_render_traceback_'\n",
      "\n",
      "During handling of the above exception, another exception occurred:\n",
      "\n",
      "Traceback (most recent call last):\n",
      "  File \"D:\\anaconda\\lib\\site-packages\\IPython\\core\\ultratb.py\", line 1169, in get_records\n",
      "    return _fixed_getinnerframes(etb, number_of_lines_of_context, tb_offset)\n",
      "  File \"D:\\anaconda\\lib\\site-packages\\IPython\\core\\ultratb.py\", line 316, in wrapped\n",
      "    return f(*args, **kwargs)\n",
      "  File \"D:\\anaconda\\lib\\site-packages\\IPython\\core\\ultratb.py\", line 350, in _fixed_getinnerframes\n",
      "    records = fix_frame_records_filenames(inspect.getinnerframes(etb, context))\n",
      "  File \"D:\\anaconda\\lib\\inspect.py\", line 1502, in getinnerframes\n",
      "    frameinfo = (tb.tb_frame,) + getframeinfo(tb, context)\n",
      "  File \"D:\\anaconda\\lib\\inspect.py\", line 1460, in getframeinfo\n",
      "    filename = getsourcefile(frame) or getfile(frame)\n",
      "  File \"D:\\anaconda\\lib\\inspect.py\", line 696, in getsourcefile\n",
      "    if getattr(getmodule(object, filename), '__loader__', None) is not None:\n",
      "  File \"D:\\anaconda\\lib\\inspect.py\", line 733, in getmodule\n",
      "    if ismodule(module) and hasattr(module, '__file__'):\n",
      "  File \"D:\\anaconda\\lib\\site-packages\\tensorflow\\__init__.py\", line 50, in __getattr__\n",
      "    module = self._load()\n",
      "  File \"D:\\anaconda\\lib\\site-packages\\tensorflow\\__init__.py\", line 44, in _load\n",
      "    module = _importlib.import_module(self.__name__)\n",
      "  File \"D:\\anaconda\\lib\\importlib\\__init__.py\", line 127, in import_module\n",
      "    return _bootstrap._gcd_import(name[level:], package, level)\n",
      "  File \"<frozen importlib._bootstrap>\", line 1006, in _gcd_import\n",
      "  File \"<frozen importlib._bootstrap>\", line 983, in _find_and_load\n",
      "  File \"<frozen importlib._bootstrap>\", line 965, in _find_and_load_unlocked\n",
      "ModuleNotFoundError: No module named 'tensorflow_core.estimator'\n",
      "Traceback (most recent call last):\n",
      "  File \"D:\\anaconda\\lib\\site-packages\\IPython\\core\\interactiveshell.py\", line 3417, in run_code\n",
      "    exec(code_obj, self.user_global_ns, self.user_ns)\n",
      "  File \"<ipython-input-13-4b54e0986ec4>\", line 1, in <module>\n",
      "    loans = pd.read_csv('loan_data.csv')\n",
      "  File \"D:\\anaconda\\lib\\site-packages\\pandas\\io\\parsers.py\", line 686, in read_csv\n",
      "    return _read(filepath_or_buffer, kwds)\n",
      "  File \"D:\\anaconda\\lib\\site-packages\\pandas\\io\\parsers.py\", line 452, in _read\n",
      "    parser = TextFileReader(fp_or_buf, **kwds)\n",
      "  File \"D:\\anaconda\\lib\\site-packages\\pandas\\io\\parsers.py\", line 936, in __init__\n",
      "    self._make_engine(self.engine)\n",
      "  File \"D:\\anaconda\\lib\\site-packages\\pandas\\io\\parsers.py\", line 1168, in _make_engine\n",
      "    self._engine = CParserWrapper(self.f, **self.options)\n",
      "  File \"D:\\anaconda\\lib\\site-packages\\pandas\\io\\parsers.py\", line 1998, in __init__\n",
      "    self._reader = parsers.TextReader(src, **kwds)\n",
      "  File \"pandas\\_libs\\parsers.pyx\", line 361, in pandas._libs.parsers.TextReader.__cinit__\n",
      "  File \"pandas\\_libs\\parsers.pyx\", line 653, in pandas._libs.parsers.TextReader._setup_parser_source\n",
      "FileNotFoundError: [Errno 2] No such file or directory: 'loan_data.csv'\n",
      "\n",
      "During handling of the above exception, another exception occurred:\n",
      "\n",
      "Traceback (most recent call last):\n",
      "  File \"D:\\anaconda\\lib\\site-packages\\IPython\\core\\interactiveshell.py\", line 2044, in showtraceback\n",
      "    stb = value._render_traceback_()\n",
      "AttributeError: 'FileNotFoundError' object has no attribute '_render_traceback_'\n",
      "\n",
      "During handling of the above exception, another exception occurred:\n",
      "\n",
      "Traceback (most recent call last):\n",
      "  File \"D:\\anaconda\\lib\\site-packages\\IPython\\core\\interactiveshell.py\", line 3337, in run_ast_nodes\n",
      "    if (await self.run_code(code, result,  async_=asy)):\n",
      "  File \"D:\\anaconda\\lib\\site-packages\\IPython\\core\\interactiveshell.py\", line 3434, in run_code\n",
      "    self.showtraceback(running_compiled_code=True)\n",
      "  File \"D:\\anaconda\\lib\\site-packages\\IPython\\core\\interactiveshell.py\", line 2047, in showtraceback\n",
      "    value, tb, tb_offset=tb_offset)\n",
      "  File \"D:\\anaconda\\lib\\site-packages\\IPython\\core\\ultratb.py\", line 1436, in structured_traceback\n",
      "    self, etype, value, tb, tb_offset, number_of_lines_of_context)\n",
      "  File \"D:\\anaconda\\lib\\site-packages\\IPython\\core\\ultratb.py\", line 1336, in structured_traceback\n",
      "    self, etype, value, tb, tb_offset, number_of_lines_of_context\n",
      "  File \"D:\\anaconda\\lib\\site-packages\\IPython\\core\\ultratb.py\", line 1193, in structured_traceback\n",
      "    tb_offset)\n",
      "  File \"D:\\anaconda\\lib\\site-packages\\IPython\\core\\ultratb.py\", line 1150, in format_exception_as_a_whole\n",
      "    last_unique, recursion_repeat = find_recursion(orig_etype, evalue, records)\n",
      "  File \"D:\\anaconda\\lib\\site-packages\\IPython\\core\\ultratb.py\", line 451, in find_recursion\n",
      "    return len(records), 0\n",
      "TypeError: object of type 'NoneType' has no len()\n",
      "\n",
      "During handling of the above exception, another exception occurred:\n",
      "\n",
      "Traceback (most recent call last):\n",
      "  File \"D:\\anaconda\\lib\\site-packages\\IPython\\core\\interactiveshell.py\", line 2044, in showtraceback\n",
      "    stb = value._render_traceback_()\n",
      "AttributeError: 'TypeError' object has no attribute '_render_traceback_'\n",
      "\n",
      "During handling of the above exception, another exception occurred:\n",
      "\n",
      "Traceback (most recent call last):\n",
      "  File \"D:\\anaconda\\lib\\site-packages\\IPython\\core\\interactiveshell.py\", line 2922, in _run_cell\n",
      "    return runner(coro)\n",
      "  File \"D:\\anaconda\\lib\\site-packages\\IPython\\core\\async_helpers.py\", line 68, in _pseudo_sync_runner\n",
      "    coro.send(None)\n",
      "  File \"D:\\anaconda\\lib\\site-packages\\IPython\\core\\interactiveshell.py\", line 3146, in run_cell_async\n",
      "    interactivity=interactivity, compiler=compiler, result=result)\n",
      "  File \"D:\\anaconda\\lib\\site-packages\\IPython\\core\\interactiveshell.py\", line 3356, in run_ast_nodes\n",
      "    self.showtraceback()\n",
      "  File \"D:\\anaconda\\lib\\site-packages\\IPython\\core\\interactiveshell.py\", line 2047, in showtraceback\n",
      "    value, tb, tb_offset=tb_offset)\n",
      "  File \"D:\\anaconda\\lib\\site-packages\\IPython\\core\\ultratb.py\", line 1436, in structured_traceback\n",
      "    self, etype, value, tb, tb_offset, number_of_lines_of_context)\n",
      "  File \"D:\\anaconda\\lib\\site-packages\\IPython\\core\\ultratb.py\", line 1336, in structured_traceback\n",
      "    self, etype, value, tb, tb_offset, number_of_lines_of_context\n",
      "  File \"D:\\anaconda\\lib\\site-packages\\IPython\\core\\ultratb.py\", line 1211, in structured_traceback\n",
      "    chained_exceptions_tb_offset)\n",
      "  File \"D:\\anaconda\\lib\\site-packages\\IPython\\core\\ultratb.py\", line 1150, in format_exception_as_a_whole\n",
      "    last_unique, recursion_repeat = find_recursion(orig_etype, evalue, records)\n",
      "  File \"D:\\anaconda\\lib\\site-packages\\IPython\\core\\ultratb.py\", line 451, in find_recursion\n",
      "    return len(records), 0\n",
      "TypeError: object of type 'NoneType' has no len()\n",
      "\n",
      "During handling of the above exception, another exception occurred:\n",
      "\n",
      "Traceback (most recent call last):\n",
      "  File \"D:\\anaconda\\lib\\site-packages\\IPython\\core\\interactiveshell.py\", line 2044, in showtraceback\n",
      "    stb = value._render_traceback_()\n",
      "AttributeError: 'TypeError' object has no attribute '_render_traceback_'\n",
      "\n",
      "During handling of the above exception, another exception occurred:\n",
      "\n",
      "Traceback (most recent call last):\n",
      "  File \"D:\\anaconda\\lib\\site-packages\\IPython\\core\\ultratb.py\", line 1169, in get_records\n",
      "    return _fixed_getinnerframes(etb, number_of_lines_of_context, tb_offset)\n",
      "  File \"D:\\anaconda\\lib\\site-packages\\IPython\\core\\ultratb.py\", line 316, in wrapped\n",
      "    return f(*args, **kwargs)\n",
      "  File \"D:\\anaconda\\lib\\site-packages\\IPython\\core\\ultratb.py\", line 350, in _fixed_getinnerframes\n",
      "    records = fix_frame_records_filenames(inspect.getinnerframes(etb, context))\n",
      "  File \"D:\\anaconda\\lib\\inspect.py\", line 1502, in getinnerframes\n",
      "    frameinfo = (tb.tb_frame,) + getframeinfo(tb, context)\n",
      "  File \"D:\\anaconda\\lib\\inspect.py\", line 1460, in getframeinfo\n",
      "    filename = getsourcefile(frame) or getfile(frame)\n",
      "  File \"D:\\anaconda\\lib\\inspect.py\", line 696, in getsourcefile\n",
      "    if getattr(getmodule(object, filename), '__loader__', None) is not None:\n",
      "  File \"D:\\anaconda\\lib\\inspect.py\", line 733, in getmodule\n",
      "    if ismodule(module) and hasattr(module, '__file__'):\n",
      "  File \"D:\\anaconda\\lib\\site-packages\\tensorflow\\__init__.py\", line 50, in __getattr__\n",
      "    module = self._load()\n",
      "  File \"D:\\anaconda\\lib\\site-packages\\tensorflow\\__init__.py\", line 44, in _load\n",
      "    module = _importlib.import_module(self.__name__)\n",
      "  File \"D:\\anaconda\\lib\\importlib\\__init__.py\", line 127, in import_module\n",
      "    return _bootstrap._gcd_import(name[level:], package, level)\n",
      "  File \"<frozen importlib._bootstrap>\", line 1006, in _gcd_import\n",
      "  File \"<frozen importlib._bootstrap>\", line 983, in _find_and_load\n",
      "  File \"<frozen importlib._bootstrap>\", line 965, in _find_and_load_unlocked\n",
      "ModuleNotFoundError: No module named 'tensorflow_core.estimator'\n"
     ]
    }
   ],
   "source": [
    "loans = pd.read_csv('loan_data.csv')"
   ]
  },
  {
   "cell_type": "code",
   "execution_count": null,
   "metadata": {},
   "outputs": [],
   "source": []
  },
  {
   "cell_type": "code",
   "execution_count": null,
   "metadata": {},
   "outputs": [],
   "source": []
  },
  {
   "cell_type": "code",
   "execution_count": null,
   "metadata": {},
   "outputs": [],
   "source": []
  },
  {
   "cell_type": "code",
   "execution_count": null,
   "metadata": {},
   "outputs": [],
   "source": []
  },
  {
   "cell_type": "code",
   "execution_count": 3,
   "metadata": {},
   "outputs": [],
   "source": [
    "df = pd.read_csv('iris.csv')"
   ]
  },
  {
   "cell_type": "code",
   "execution_count": null,
   "metadata": {},
   "outputs": [],
   "source": []
  },
  {
   "cell_type": "code",
   "execution_count": 4,
   "metadata": {},
   "outputs": [
    {
     "data": {
      "text/html": [
       "<div>\n",
       "<style scoped>\n",
       "    .dataframe tbody tr th:only-of-type {\n",
       "        vertical-align: middle;\n",
       "    }\n",
       "\n",
       "    .dataframe tbody tr th {\n",
       "        vertical-align: top;\n",
       "    }\n",
       "\n",
       "    .dataframe thead th {\n",
       "        text-align: right;\n",
       "    }\n",
       "</style>\n",
       "<table border=\"1\" class=\"dataframe\">\n",
       "  <thead>\n",
       "    <tr style=\"text-align: right;\">\n",
       "      <th></th>\n",
       "      <th>sepal length (cm)</th>\n",
       "      <th>sepal width (cm)</th>\n",
       "      <th>petal length (cm)</th>\n",
       "      <th>petal width (cm)</th>\n",
       "      <th>target</th>\n",
       "    </tr>\n",
       "  </thead>\n",
       "  <tbody>\n",
       "    <tr>\n",
       "      <th>0</th>\n",
       "      <td>5.1</td>\n",
       "      <td>3.5</td>\n",
       "      <td>1.4</td>\n",
       "      <td>0.2</td>\n",
       "      <td>0.0</td>\n",
       "    </tr>\n",
       "    <tr>\n",
       "      <th>1</th>\n",
       "      <td>4.9</td>\n",
       "      <td>3.0</td>\n",
       "      <td>1.4</td>\n",
       "      <td>0.2</td>\n",
       "      <td>0.0</td>\n",
       "    </tr>\n",
       "    <tr>\n",
       "      <th>2</th>\n",
       "      <td>4.7</td>\n",
       "      <td>3.2</td>\n",
       "      <td>1.3</td>\n",
       "      <td>0.2</td>\n",
       "      <td>0.0</td>\n",
       "    </tr>\n",
       "    <tr>\n",
       "      <th>3</th>\n",
       "      <td>4.6</td>\n",
       "      <td>3.1</td>\n",
       "      <td>1.5</td>\n",
       "      <td>0.2</td>\n",
       "      <td>0.0</td>\n",
       "    </tr>\n",
       "    <tr>\n",
       "      <th>4</th>\n",
       "      <td>5.0</td>\n",
       "      <td>3.6</td>\n",
       "      <td>1.4</td>\n",
       "      <td>0.2</td>\n",
       "      <td>0.0</td>\n",
       "    </tr>\n",
       "  </tbody>\n",
       "</table>\n",
       "</div>"
      ],
      "text/plain": [
       "   sepal length (cm)  sepal width (cm)  petal length (cm)  petal width (cm)  \\\n",
       "0                5.1               3.5                1.4               0.2   \n",
       "1                4.9               3.0                1.4               0.2   \n",
       "2                4.7               3.2                1.3               0.2   \n",
       "3                4.6               3.1                1.5               0.2   \n",
       "4                5.0               3.6                1.4               0.2   \n",
       "\n",
       "   target  \n",
       "0     0.0  \n",
       "1     0.0  \n",
       "2     0.0  \n",
       "3     0.0  \n",
       "4     0.0  "
      ]
     },
     "execution_count": 4,
     "metadata": {},
     "output_type": "execute_result"
    }
   ],
   "source": [
    "df.head()"
   ]
  },
  {
   "cell_type": "code",
   "execution_count": null,
   "metadata": {},
   "outputs": [],
   "source": []
  },
  {
   "cell_type": "code",
   "execution_count": 5,
   "metadata": {},
   "outputs": [],
   "source": [
    "df.columns = ['sepal_length','sepal_width','petal_length','petal_width','target']"
   ]
  },
  {
   "cell_type": "code",
   "execution_count": null,
   "metadata": {},
   "outputs": [],
   "source": []
  },
  {
   "cell_type": "code",
   "execution_count": 6,
   "metadata": {},
   "outputs": [],
   "source": [
    "X = df.drop('target',axis=1)\n",
    "y = df['target'].apply(int)"
   ]
  },
  {
   "cell_type": "code",
   "execution_count": null,
   "metadata": {},
   "outputs": [],
   "source": []
  },
  {
   "cell_type": "markdown",
   "metadata": {},
   "source": [
    "## Train Test Split"
   ]
  },
  {
   "cell_type": "code",
   "execution_count": 7,
   "metadata": {},
   "outputs": [],
   "source": [
    "from sklearn.model_selection import train_test_split"
   ]
  },
  {
   "cell_type": "code",
   "execution_count": null,
   "metadata": {},
   "outputs": [],
   "source": []
  },
  {
   "cell_type": "code",
   "execution_count": 8,
   "metadata": {},
   "outputs": [],
   "source": [
    "X_train, X_test, y_train, y_test = train_test_split(X, y, test_size=0.3)"
   ]
  },
  {
   "cell_type": "code",
   "execution_count": null,
   "metadata": {},
   "outputs": [],
   "source": []
  },
  {
   "cell_type": "markdown",
   "metadata": {},
   "source": [
    "# Estimators\n",
    "\n",
    "Let's show you how to use the simpler Estimator interface!"
   ]
  },
  {
   "cell_type": "code",
   "execution_count": 9,
   "metadata": {},
   "outputs": [],
   "source": [
    "import tensorflow as tf"
   ]
  },
  {
   "cell_type": "code",
   "execution_count": null,
   "metadata": {},
   "outputs": [],
   "source": []
  },
  {
   "cell_type": "markdown",
   "metadata": {},
   "source": [
    "## Feature Columns"
   ]
  },
  {
   "cell_type": "code",
   "execution_count": 9,
   "metadata": {},
   "outputs": [
    {
     "data": {
      "text/plain": [
       "Index(['sepal_length', 'sepal_width', 'petal_length', 'petal_width'], dtype='object')"
      ]
     },
     "execution_count": 9,
     "metadata": {},
     "output_type": "execute_result"
    }
   ],
   "source": [
    "X.columns"
   ]
  },
  {
   "cell_type": "code",
   "execution_count": 10,
   "metadata": {},
   "outputs": [],
   "source": [
    "feat_cols = []\n",
    "\n",
    "for col in X.columns:\n",
    "    feat_cols.append(tf.feature_column.numeric_column(col))"
   ]
  },
  {
   "cell_type": "code",
   "execution_count": null,
   "metadata": {},
   "outputs": [],
   "source": []
  },
  {
   "cell_type": "code",
   "execution_count": 11,
   "metadata": {},
   "outputs": [
    {
     "data": {
      "text/plain": [
       "[NumericColumn(key='sepal_length', shape=(1,), default_value=None, dtype=tf.float32, normalizer_fn=None),\n",
       " NumericColumn(key='sepal_width', shape=(1,), default_value=None, dtype=tf.float32, normalizer_fn=None),\n",
       " NumericColumn(key='petal_length', shape=(1,), default_value=None, dtype=tf.float32, normalizer_fn=None),\n",
       " NumericColumn(key='petal_width', shape=(1,), default_value=None, dtype=tf.float32, normalizer_fn=None)]"
      ]
     },
     "execution_count": 11,
     "metadata": {},
     "output_type": "execute_result"
    }
   ],
   "source": [
    "feat_cols"
   ]
  },
  {
   "cell_type": "code",
   "execution_count": null,
   "metadata": {},
   "outputs": [],
   "source": []
  },
  {
   "cell_type": "markdown",
   "metadata": {},
   "source": [
    "## Input Function"
   ]
  },
  {
   "cell_type": "code",
   "execution_count": null,
   "metadata": {},
   "outputs": [
    {
     "name": "stderr",
     "output_type": "stream",
     "text": [
      "ERROR:root:Internal Python error in the inspect module.\n",
      "Below is the traceback from this internal error.\n",
      "\n",
      "ERROR:root:Internal Python error in the inspect module.\n",
      "Below is the traceback from this internal error.\n",
      "\n",
      "ERROR:root:Internal Python error in the inspect module.\n",
      "Below is the traceback from this internal error.\n",
      "\n"
     ]
    },
    {
     "name": "stdout",
     "output_type": "stream",
     "text": [
      "Traceback (most recent call last):\n",
      "  File \"D:\\anaconda\\lib\\site-packages\\IPython\\core\\interactiveshell.py\", line 3417, in run_code\n",
      "    exec(code_obj, self.user_global_ns, self.user_ns)\n",
      "  File \"<ipython-input-12-6ec04152f30f>\", line 2, in <module>\n",
      "    input_func = tf.estimator.inputs.pandas_input_fn(x=X_train,y=y_train,batch_size=10,num_epochs=5,shuffle=True)\n",
      "AttributeError: module 'tensorflow' has no attribute 'estimator'\n",
      "\n",
      "During handling of the above exception, another exception occurred:\n",
      "\n",
      "Traceback (most recent call last):\n",
      "  File \"D:\\anaconda\\lib\\site-packages\\IPython\\core\\interactiveshell.py\", line 2044, in showtraceback\n",
      "    stb = value._render_traceback_()\n",
      "AttributeError: 'AttributeError' object has no attribute '_render_traceback_'\n",
      "\n",
      "During handling of the above exception, another exception occurred:\n",
      "\n",
      "Traceback (most recent call last):\n",
      "  File \"D:\\anaconda\\lib\\site-packages\\IPython\\core\\ultratb.py\", line 1169, in get_records\n",
      "    return _fixed_getinnerframes(etb, number_of_lines_of_context, tb_offset)\n",
      "  File \"D:\\anaconda\\lib\\site-packages\\IPython\\core\\ultratb.py\", line 316, in wrapped\n",
      "    return f(*args, **kwargs)\n",
      "  File \"D:\\anaconda\\lib\\site-packages\\IPython\\core\\ultratb.py\", line 350, in _fixed_getinnerframes\n",
      "    records = fix_frame_records_filenames(inspect.getinnerframes(etb, context))\n",
      "  File \"D:\\anaconda\\lib\\inspect.py\", line 1502, in getinnerframes\n",
      "    frameinfo = (tb.tb_frame,) + getframeinfo(tb, context)\n",
      "  File \"D:\\anaconda\\lib\\inspect.py\", line 1460, in getframeinfo\n",
      "    filename = getsourcefile(frame) or getfile(frame)\n",
      "  File \"D:\\anaconda\\lib\\inspect.py\", line 696, in getsourcefile\n",
      "    if getattr(getmodule(object, filename), '__loader__', None) is not None:\n",
      "  File \"D:\\anaconda\\lib\\inspect.py\", line 733, in getmodule\n",
      "    if ismodule(module) and hasattr(module, '__file__'):\n",
      "  File \"D:\\anaconda\\lib\\site-packages\\tensorflow\\__init__.py\", line 50, in __getattr__\n",
      "    module = self._load()\n",
      "  File \"D:\\anaconda\\lib\\site-packages\\tensorflow\\__init__.py\", line 44, in _load\n",
      "    module = _importlib.import_module(self.__name__)\n",
      "  File \"D:\\anaconda\\lib\\importlib\\__init__.py\", line 127, in import_module\n",
      "    return _bootstrap._gcd_import(name[level:], package, level)\n",
      "  File \"<frozen importlib._bootstrap>\", line 1006, in _gcd_import\n",
      "  File \"<frozen importlib._bootstrap>\", line 983, in _find_and_load\n",
      "  File \"<frozen importlib._bootstrap>\", line 965, in _find_and_load_unlocked\n",
      "ModuleNotFoundError: No module named 'tensorflow_core.estimator'\n",
      "Traceback (most recent call last):\n",
      "  File \"D:\\anaconda\\lib\\site-packages\\IPython\\core\\interactiveshell.py\", line 3417, in run_code\n",
      "    exec(code_obj, self.user_global_ns, self.user_ns)\n",
      "  File \"<ipython-input-12-6ec04152f30f>\", line 2, in <module>\n",
      "    input_func = tf.estimator.inputs.pandas_input_fn(x=X_train,y=y_train,batch_size=10,num_epochs=5,shuffle=True)\n",
      "AttributeError: module 'tensorflow' has no attribute 'estimator'\n",
      "\n",
      "During handling of the above exception, another exception occurred:\n",
      "\n",
      "Traceback (most recent call last):\n",
      "  File \"D:\\anaconda\\lib\\site-packages\\IPython\\core\\interactiveshell.py\", line 2044, in showtraceback\n",
      "    stb = value._render_traceback_()\n",
      "AttributeError: 'AttributeError' object has no attribute '_render_traceback_'\n",
      "\n",
      "During handling of the above exception, another exception occurred:\n",
      "\n",
      "Traceback (most recent call last):\n",
      "  File \"D:\\anaconda\\lib\\site-packages\\IPython\\core\\interactiveshell.py\", line 3337, in run_ast_nodes\n",
      "    if (await self.run_code(code, result,  async_=asy)):\n",
      "  File \"D:\\anaconda\\lib\\site-packages\\IPython\\core\\interactiveshell.py\", line 3434, in run_code\n",
      "    self.showtraceback(running_compiled_code=True)\n",
      "  File \"D:\\anaconda\\lib\\site-packages\\IPython\\core\\interactiveshell.py\", line 2047, in showtraceback\n",
      "    value, tb, tb_offset=tb_offset)\n",
      "  File \"D:\\anaconda\\lib\\site-packages\\IPython\\core\\ultratb.py\", line 1436, in structured_traceback\n",
      "    self, etype, value, tb, tb_offset, number_of_lines_of_context)\n",
      "  File \"D:\\anaconda\\lib\\site-packages\\IPython\\core\\ultratb.py\", line 1336, in structured_traceback\n",
      "    self, etype, value, tb, tb_offset, number_of_lines_of_context\n",
      "  File \"D:\\anaconda\\lib\\site-packages\\IPython\\core\\ultratb.py\", line 1193, in structured_traceback\n",
      "    tb_offset)\n",
      "  File \"D:\\anaconda\\lib\\site-packages\\IPython\\core\\ultratb.py\", line 1150, in format_exception_as_a_whole\n",
      "    last_unique, recursion_repeat = find_recursion(orig_etype, evalue, records)\n",
      "  File \"D:\\anaconda\\lib\\site-packages\\IPython\\core\\ultratb.py\", line 451, in find_recursion\n",
      "    return len(records), 0\n",
      "TypeError: object of type 'NoneType' has no len()\n",
      "\n",
      "During handling of the above exception, another exception occurred:\n",
      "\n",
      "Traceback (most recent call last):\n",
      "  File \"D:\\anaconda\\lib\\site-packages\\IPython\\core\\interactiveshell.py\", line 2044, in showtraceback\n",
      "    stb = value._render_traceback_()\n",
      "AttributeError: 'TypeError' object has no attribute '_render_traceback_'\n",
      "\n",
      "During handling of the above exception, another exception occurred:\n",
      "\n",
      "Traceback (most recent call last):\n",
      "  File \"D:\\anaconda\\lib\\site-packages\\IPython\\core\\ultratb.py\", line 1169, in get_records\n",
      "    return _fixed_getinnerframes(etb, number_of_lines_of_context, tb_offset)\n",
      "  File \"D:\\anaconda\\lib\\site-packages\\IPython\\core\\ultratb.py\", line 316, in wrapped\n",
      "    return f(*args, **kwargs)\n",
      "  File \"D:\\anaconda\\lib\\site-packages\\IPython\\core\\ultratb.py\", line 350, in _fixed_getinnerframes\n",
      "    records = fix_frame_records_filenames(inspect.getinnerframes(etb, context))\n",
      "  File \"D:\\anaconda\\lib\\inspect.py\", line 1502, in getinnerframes\n",
      "    frameinfo = (tb.tb_frame,) + getframeinfo(tb, context)\n",
      "  File \"D:\\anaconda\\lib\\inspect.py\", line 1460, in getframeinfo\n",
      "    filename = getsourcefile(frame) or getfile(frame)\n",
      "  File \"D:\\anaconda\\lib\\inspect.py\", line 696, in getsourcefile\n",
      "    if getattr(getmodule(object, filename), '__loader__', None) is not None:\n",
      "  File \"D:\\anaconda\\lib\\inspect.py\", line 733, in getmodule\n",
      "    if ismodule(module) and hasattr(module, '__file__'):\n",
      "  File \"D:\\anaconda\\lib\\site-packages\\tensorflow\\__init__.py\", line 50, in __getattr__\n",
      "    module = self._load()\n",
      "  File \"D:\\anaconda\\lib\\site-packages\\tensorflow\\__init__.py\", line 44, in _load\n",
      "    module = _importlib.import_module(self.__name__)\n",
      "  File \"D:\\anaconda\\lib\\importlib\\__init__.py\", line 127, in import_module\n",
      "    return _bootstrap._gcd_import(name[level:], package, level)\n",
      "  File \"<frozen importlib._bootstrap>\", line 1006, in _gcd_import\n",
      "  File \"<frozen importlib._bootstrap>\", line 983, in _find_and_load\n",
      "  File \"<frozen importlib._bootstrap>\", line 965, in _find_and_load_unlocked\n",
      "ModuleNotFoundError: No module named 'tensorflow_core.estimator'\n",
      "Traceback (most recent call last):\n",
      "  File \"D:\\anaconda\\lib\\site-packages\\IPython\\core\\interactiveshell.py\", line 3417, in run_code\n",
      "    exec(code_obj, self.user_global_ns, self.user_ns)\n",
      "  File \"<ipython-input-12-6ec04152f30f>\", line 2, in <module>\n",
      "    input_func = tf.estimator.inputs.pandas_input_fn(x=X_train,y=y_train,batch_size=10,num_epochs=5,shuffle=True)\n",
      "AttributeError: module 'tensorflow' has no attribute 'estimator'\n",
      "\n",
      "During handling of the above exception, another exception occurred:\n",
      "\n",
      "Traceback (most recent call last):\n",
      "  File \"D:\\anaconda\\lib\\site-packages\\IPython\\core\\interactiveshell.py\", line 2044, in showtraceback\n",
      "    stb = value._render_traceback_()\n",
      "AttributeError: 'AttributeError' object has no attribute '_render_traceback_'\n",
      "\n",
      "During handling of the above exception, another exception occurred:\n",
      "\n",
      "Traceback (most recent call last):\n",
      "  File \"D:\\anaconda\\lib\\site-packages\\IPython\\core\\interactiveshell.py\", line 3337, in run_ast_nodes\n",
      "    if (await self.run_code(code, result,  async_=asy)):\n",
      "  File \"D:\\anaconda\\lib\\site-packages\\IPython\\core\\interactiveshell.py\", line 3434, in run_code\n",
      "    self.showtraceback(running_compiled_code=True)\n",
      "  File \"D:\\anaconda\\lib\\site-packages\\IPython\\core\\interactiveshell.py\", line 2047, in showtraceback\n",
      "    value, tb, tb_offset=tb_offset)\n",
      "  File \"D:\\anaconda\\lib\\site-packages\\IPython\\core\\ultratb.py\", line 1436, in structured_traceback\n",
      "    self, etype, value, tb, tb_offset, number_of_lines_of_context)\n",
      "  File \"D:\\anaconda\\lib\\site-packages\\IPython\\core\\ultratb.py\", line 1336, in structured_traceback\n",
      "    self, etype, value, tb, tb_offset, number_of_lines_of_context\n",
      "  File \"D:\\anaconda\\lib\\site-packages\\IPython\\core\\ultratb.py\", line 1193, in structured_traceback\n",
      "    tb_offset)\n",
      "  File \"D:\\anaconda\\lib\\site-packages\\IPython\\core\\ultratb.py\", line 1150, in format_exception_as_a_whole\n",
      "    last_unique, recursion_repeat = find_recursion(orig_etype, evalue, records)\n",
      "  File \"D:\\anaconda\\lib\\site-packages\\IPython\\core\\ultratb.py\", line 451, in find_recursion\n",
      "    return len(records), 0\n",
      "TypeError: object of type 'NoneType' has no len()\n",
      "\n",
      "During handling of the above exception, another exception occurred:\n",
      "\n",
      "Traceback (most recent call last):\n",
      "  File \"D:\\anaconda\\lib\\site-packages\\IPython\\core\\interactiveshell.py\", line 2044, in showtraceback\n",
      "    stb = value._render_traceback_()\n",
      "AttributeError: 'TypeError' object has no attribute '_render_traceback_'\n",
      "\n",
      "During handling of the above exception, another exception occurred:\n",
      "\n",
      "Traceback (most recent call last):\n",
      "  File \"D:\\anaconda\\lib\\site-packages\\IPython\\core\\interactiveshell.py\", line 2922, in _run_cell\n",
      "    return runner(coro)\n",
      "  File \"D:\\anaconda\\lib\\site-packages\\IPython\\core\\async_helpers.py\", line 68, in _pseudo_sync_runner\n",
      "    coro.send(None)\n",
      "  File \"D:\\anaconda\\lib\\site-packages\\IPython\\core\\interactiveshell.py\", line 3146, in run_cell_async\n",
      "    interactivity=interactivity, compiler=compiler, result=result)\n",
      "  File \"D:\\anaconda\\lib\\site-packages\\IPython\\core\\interactiveshell.py\", line 3356, in run_ast_nodes\n",
      "    self.showtraceback()\n",
      "  File \"D:\\anaconda\\lib\\site-packages\\IPython\\core\\interactiveshell.py\", line 2047, in showtraceback\n",
      "    value, tb, tb_offset=tb_offset)\n",
      "  File \"D:\\anaconda\\lib\\site-packages\\IPython\\core\\ultratb.py\", line 1436, in structured_traceback\n",
      "    self, etype, value, tb, tb_offset, number_of_lines_of_context)\n",
      "  File \"D:\\anaconda\\lib\\site-packages\\IPython\\core\\ultratb.py\", line 1336, in structured_traceback\n",
      "    self, etype, value, tb, tb_offset, number_of_lines_of_context\n",
      "  File \"D:\\anaconda\\lib\\site-packages\\IPython\\core\\ultratb.py\", line 1211, in structured_traceback\n",
      "    chained_exceptions_tb_offset)\n",
      "  File \"D:\\anaconda\\lib\\site-packages\\IPython\\core\\ultratb.py\", line 1150, in format_exception_as_a_whole\n",
      "    last_unique, recursion_repeat = find_recursion(orig_etype, evalue, records)\n",
      "  File \"D:\\anaconda\\lib\\site-packages\\IPython\\core\\ultratb.py\", line 451, in find_recursion\n",
      "    return len(records), 0\n",
      "TypeError: object of type 'NoneType' has no len()\n",
      "\n",
      "During handling of the above exception, another exception occurred:\n",
      "\n",
      "Traceback (most recent call last):\n",
      "  File \"D:\\anaconda\\lib\\site-packages\\IPython\\core\\interactiveshell.py\", line 2044, in showtraceback\n",
      "    stb = value._render_traceback_()\n",
      "AttributeError: 'TypeError' object has no attribute '_render_traceback_'\n",
      "\n",
      "During handling of the above exception, another exception occurred:\n",
      "\n",
      "Traceback (most recent call last):\n",
      "  File \"D:\\anaconda\\lib\\site-packages\\IPython\\core\\ultratb.py\", line 1169, in get_records\n",
      "    return _fixed_getinnerframes(etb, number_of_lines_of_context, tb_offset)\n",
      "  File \"D:\\anaconda\\lib\\site-packages\\IPython\\core\\ultratb.py\", line 316, in wrapped\n",
      "    return f(*args, **kwargs)\n",
      "  File \"D:\\anaconda\\lib\\site-packages\\IPython\\core\\ultratb.py\", line 350, in _fixed_getinnerframes\n",
      "    records = fix_frame_records_filenames(inspect.getinnerframes(etb, context))\n",
      "  File \"D:\\anaconda\\lib\\inspect.py\", line 1502, in getinnerframes\n",
      "    frameinfo = (tb.tb_frame,) + getframeinfo(tb, context)\n",
      "  File \"D:\\anaconda\\lib\\inspect.py\", line 1460, in getframeinfo\n",
      "    filename = getsourcefile(frame) or getfile(frame)\n",
      "  File \"D:\\anaconda\\lib\\inspect.py\", line 696, in getsourcefile\n",
      "    if getattr(getmodule(object, filename), '__loader__', None) is not None:\n",
      "  File \"D:\\anaconda\\lib\\inspect.py\", line 733, in getmodule\n",
      "    if ismodule(module) and hasattr(module, '__file__'):\n",
      "  File \"D:\\anaconda\\lib\\site-packages\\tensorflow\\__init__.py\", line 50, in __getattr__\n",
      "    module = self._load()\n",
      "  File \"D:\\anaconda\\lib\\site-packages\\tensorflow\\__init__.py\", line 44, in _load\n",
      "    module = _importlib.import_module(self.__name__)\n",
      "  File \"D:\\anaconda\\lib\\importlib\\__init__.py\", line 127, in import_module\n",
      "    return _bootstrap._gcd_import(name[level:], package, level)\n",
      "  File \"<frozen importlib._bootstrap>\", line 1006, in _gcd_import\n",
      "  File \"<frozen importlib._bootstrap>\", line 983, in _find_and_load\n",
      "  File \"<frozen importlib._bootstrap>\", line 965, in _find_and_load_unlocked\n",
      "ModuleNotFoundError: No module named 'tensorflow_core.estimator'\n"
     ]
    }
   ],
   "source": [
    "# there is also a pandas_input_fn we'll see in the exercise!!\n",
    "input_func = tf.estimator.inputs.pandas_input_fn(x=X_train,y=y_train,batch_size=10,num_epochs=5,shuffle=True)"
   ]
  },
  {
   "cell_type": "code",
   "execution_count": null,
   "metadata": {},
   "outputs": [],
   "source": []
  },
  {
   "cell_type": "code",
   "execution_count": 13,
   "metadata": {},
   "outputs": [
    {
     "name": "stdout",
     "output_type": "stream",
     "text": [
      "INFO:tensorflow:Using default config.\n",
      "WARNING:tensorflow:Using temporary folder as model directory: C:\\Users\\Marcial\\AppData\\Local\\Temp\\tmp3_l8l99d\n",
      "INFO:tensorflow:Using config: {'_model_dir': 'C:\\\\Users\\\\Marcial\\\\AppData\\\\Local\\\\Temp\\\\tmp3_l8l99d', '_tf_random_seed': None, '_save_summary_steps': 100, '_save_checkpoints_steps': None, '_save_checkpoints_secs': 600, '_session_config': None, '_keep_checkpoint_max': 5, '_keep_checkpoint_every_n_hours': 10000, '_log_step_count_steps': 100, '_train_distribute': None, '_device_fn': None, '_service': None, '_cluster_spec': <tensorflow.python.training.server_lib.ClusterSpec object at 0x0000020ED5FA2390>, '_task_type': 'worker', '_task_id': 0, '_global_id_in_cluster': 0, '_master': '', '_evaluation_master': '', '_is_chief': True, '_num_ps_replicas': 0, '_num_worker_replicas': 1}\n"
     ]
    }
   ],
   "source": [
    "classifier = tf.estimator.DNNClassifier(hidden_units=[10, 20, 10], n_classes=3,feature_columns=feat_cols)"
   ]
  },
  {
   "cell_type": "code",
   "execution_count": 14,
   "metadata": {},
   "outputs": [
    {
     "name": "stdout",
     "output_type": "stream",
     "text": [
      "INFO:tensorflow:Calling model_fn.\n",
      "INFO:tensorflow:Done calling model_fn.\n",
      "INFO:tensorflow:Create CheckpointSaverHook.\n",
      "INFO:tensorflow:Graph was finalized.\n",
      "INFO:tensorflow:Running local_init_op.\n",
      "INFO:tensorflow:Done running local_init_op.\n",
      "INFO:tensorflow:Saving checkpoints for 0 into C:\\Users\\Marcial\\AppData\\Local\\Temp\\tmp3_l8l99d\\model.ckpt.\n",
      "INFO:tensorflow:loss = 15.285385, step = 1\n",
      "INFO:tensorflow:Saving checkpoints for 50 into C:\\Users\\Marcial\\AppData\\Local\\Temp\\tmp3_l8l99d\\model.ckpt.\n",
      "INFO:tensorflow:Loss for final step: 3.4342575.\n"
     ]
    },
    {
     "data": {
      "text/plain": [
       "<tensorflow.python.estimator.canned.dnn.DNNClassifier at 0x20edb48f748>"
      ]
     },
     "execution_count": 14,
     "metadata": {},
     "output_type": "execute_result"
    }
   ],
   "source": [
    "classifier.train(input_fn=input_func,steps=50)"
   ]
  },
  {
   "cell_type": "markdown",
   "metadata": {},
   "source": [
    "## Model Evaluation\n",
    "\n",
    "** Use the predict method from the classifier model to create predictions from X_test **"
   ]
  },
  {
   "cell_type": "code",
   "execution_count": 15,
   "metadata": {
    "collapsed": true
   },
   "outputs": [],
   "source": [
    "pred_fn = tf.estimator.inputs.pandas_input_fn(x=X_test,batch_size=len(X_test),shuffle=False)"
   ]
  },
  {
   "cell_type": "code",
   "execution_count": 16,
   "metadata": {},
   "outputs": [
    {
     "name": "stdout",
     "output_type": "stream",
     "text": [
      "INFO:tensorflow:Calling model_fn.\n",
      "INFO:tensorflow:Done calling model_fn.\n",
      "INFO:tensorflow:Graph was finalized.\n",
      "INFO:tensorflow:Restoring parameters from C:\\Users\\Marcial\\AppData\\Local\\Temp\\tmp3_l8l99d\\model.ckpt-50\n",
      "INFO:tensorflow:Running local_init_op.\n",
      "INFO:tensorflow:Done running local_init_op.\n"
     ]
    }
   ],
   "source": [
    "note_predictions = list(classifier.predict(input_fn=pred_fn))"
   ]
  },
  {
   "cell_type": "code",
   "execution_count": 17,
   "metadata": {},
   "outputs": [
    {
     "data": {
      "text/plain": [
       "{'class_ids': array([2], dtype=int64),\n",
       " 'classes': array([b'2'], dtype=object),\n",
       " 'logits': array([-3.6269774 ,  0.16824062,  1.2134217 ], dtype=float32),\n",
       " 'probabilities': array([0.00581369, 0.2586391 , 0.7355472 ], dtype=float32)}"
      ]
     },
     "execution_count": 17,
     "metadata": {},
     "output_type": "execute_result"
    }
   ],
   "source": [
    "note_predictions[0]"
   ]
  },
  {
   "cell_type": "code",
   "execution_count": 18,
   "metadata": {
    "collapsed": true
   },
   "outputs": [],
   "source": [
    "final_preds  = []\n",
    "for pred in note_predictions:\n",
    "    final_preds.append(pred['class_ids'][0])"
   ]
  },
  {
   "cell_type": "markdown",
   "metadata": {},
   "source": [
    "** Now create a classification report and a Confusion Matrix. Does anything stand out to you?**"
   ]
  },
  {
   "cell_type": "code",
   "execution_count": 19,
   "metadata": {
    "collapsed": true
   },
   "outputs": [],
   "source": [
    "from sklearn.metrics import classification_report,confusion_matrix"
   ]
  },
  {
   "cell_type": "code",
   "execution_count": null,
   "metadata": {},
   "outputs": [
    {
     "name": "stderr",
     "output_type": "stream",
     "text": [
      "ERROR:root:Internal Python error in the inspect module.\n",
      "Below is the traceback from this internal error.\n",
      "\n",
      "ERROR:root:Internal Python error in the inspect module.\n",
      "Below is the traceback from this internal error.\n",
      "\n",
      "ERROR:root:Internal Python error in the inspect module.\n",
      "Below is the traceback from this internal error.\n",
      "\n"
     ]
    },
    {
     "name": "stdout",
     "output_type": "stream",
     "text": [
      "Traceback (most recent call last):\n",
      "  File \"D:\\anaconda\\lib\\site-packages\\IPython\\core\\interactiveshell.py\", line 3417, in run_code\n",
      "    exec(code_obj, self.user_global_ns, self.user_ns)\n",
      "  File \"<ipython-input-12-0d615eaf079a>\", line 1, in <module>\n",
      "    print(confusion_matrix(y_test,final_preds))\n",
      "NameError: name 'confusion_matrix' is not defined\n",
      "\n",
      "During handling of the above exception, another exception occurred:\n",
      "\n",
      "Traceback (most recent call last):\n",
      "  File \"D:\\anaconda\\lib\\site-packages\\IPython\\core\\interactiveshell.py\", line 2044, in showtraceback\n",
      "    stb = value._render_traceback_()\n",
      "AttributeError: 'NameError' object has no attribute '_render_traceback_'\n",
      "\n",
      "During handling of the above exception, another exception occurred:\n",
      "\n",
      "Traceback (most recent call last):\n",
      "  File \"D:\\anaconda\\lib\\site-packages\\IPython\\core\\ultratb.py\", line 1169, in get_records\n",
      "    return _fixed_getinnerframes(etb, number_of_lines_of_context, tb_offset)\n",
      "  File \"D:\\anaconda\\lib\\site-packages\\IPython\\core\\ultratb.py\", line 316, in wrapped\n",
      "    return f(*args, **kwargs)\n",
      "  File \"D:\\anaconda\\lib\\site-packages\\IPython\\core\\ultratb.py\", line 350, in _fixed_getinnerframes\n",
      "    records = fix_frame_records_filenames(inspect.getinnerframes(etb, context))\n",
      "  File \"D:\\anaconda\\lib\\inspect.py\", line 1502, in getinnerframes\n",
      "    frameinfo = (tb.tb_frame,) + getframeinfo(tb, context)\n",
      "  File \"D:\\anaconda\\lib\\inspect.py\", line 1460, in getframeinfo\n",
      "    filename = getsourcefile(frame) or getfile(frame)\n",
      "  File \"D:\\anaconda\\lib\\inspect.py\", line 696, in getsourcefile\n",
      "    if getattr(getmodule(object, filename), '__loader__', None) is not None:\n",
      "  File \"D:\\anaconda\\lib\\inspect.py\", line 733, in getmodule\n",
      "    if ismodule(module) and hasattr(module, '__file__'):\n",
      "  File \"D:\\anaconda\\lib\\site-packages\\tensorflow\\__init__.py\", line 50, in __getattr__\n",
      "    module = self._load()\n",
      "  File \"D:\\anaconda\\lib\\site-packages\\tensorflow\\__init__.py\", line 44, in _load\n",
      "    module = _importlib.import_module(self.__name__)\n",
      "  File \"D:\\anaconda\\lib\\importlib\\__init__.py\", line 127, in import_module\n",
      "    return _bootstrap._gcd_import(name[level:], package, level)\n",
      "  File \"<frozen importlib._bootstrap>\", line 1006, in _gcd_import\n",
      "  File \"<frozen importlib._bootstrap>\", line 983, in _find_and_load\n",
      "  File \"<frozen importlib._bootstrap>\", line 965, in _find_and_load_unlocked\n",
      "ModuleNotFoundError: No module named 'tensorflow_core.estimator'\n",
      "ERROR! Session/line number was not unique in database. History logging moved to new session 850\n",
      "Traceback (most recent call last):\n",
      "  File \"D:\\anaconda\\lib\\site-packages\\IPython\\core\\interactiveshell.py\", line 3417, in run_code\n",
      "    exec(code_obj, self.user_global_ns, self.user_ns)\n",
      "  File \"<ipython-input-12-0d615eaf079a>\", line 1, in <module>\n",
      "    print(confusion_matrix(y_test,final_preds))\n",
      "NameError: name 'confusion_matrix' is not defined\n",
      "\n",
      "During handling of the above exception, another exception occurred:\n",
      "\n",
      "Traceback (most recent call last):\n",
      "  File \"D:\\anaconda\\lib\\site-packages\\IPython\\core\\interactiveshell.py\", line 2044, in showtraceback\n",
      "    stb = value._render_traceback_()\n",
      "AttributeError: 'NameError' object has no attribute '_render_traceback_'\n",
      "\n",
      "During handling of the above exception, another exception occurred:\n",
      "\n",
      "Traceback (most recent call last):\n",
      "  File \"D:\\anaconda\\lib\\site-packages\\IPython\\core\\interactiveshell.py\", line 3337, in run_ast_nodes\n",
      "    if (await self.run_code(code, result,  async_=asy)):\n",
      "  File \"D:\\anaconda\\lib\\site-packages\\IPython\\core\\interactiveshell.py\", line 3434, in run_code\n",
      "    self.showtraceback(running_compiled_code=True)\n",
      "  File \"D:\\anaconda\\lib\\site-packages\\IPython\\core\\interactiveshell.py\", line 2047, in showtraceback\n",
      "    value, tb, tb_offset=tb_offset)\n",
      "  File \"D:\\anaconda\\lib\\site-packages\\IPython\\core\\ultratb.py\", line 1436, in structured_traceback\n",
      "    self, etype, value, tb, tb_offset, number_of_lines_of_context)\n",
      "  File \"D:\\anaconda\\lib\\site-packages\\IPython\\core\\ultratb.py\", line 1336, in structured_traceback\n",
      "    self, etype, value, tb, tb_offset, number_of_lines_of_context\n",
      "  File \"D:\\anaconda\\lib\\site-packages\\IPython\\core\\ultratb.py\", line 1193, in structured_traceback\n",
      "    tb_offset)\n",
      "  File \"D:\\anaconda\\lib\\site-packages\\IPython\\core\\ultratb.py\", line 1150, in format_exception_as_a_whole\n",
      "    last_unique, recursion_repeat = find_recursion(orig_etype, evalue, records)\n",
      "  File \"D:\\anaconda\\lib\\site-packages\\IPython\\core\\ultratb.py\", line 451, in find_recursion\n",
      "    return len(records), 0\n",
      "TypeError: object of type 'NoneType' has no len()\n",
      "\n",
      "During handling of the above exception, another exception occurred:\n",
      "\n",
      "Traceback (most recent call last):\n",
      "  File \"D:\\anaconda\\lib\\site-packages\\IPython\\core\\interactiveshell.py\", line 2044, in showtraceback\n",
      "    stb = value._render_traceback_()\n",
      "AttributeError: 'TypeError' object has no attribute '_render_traceback_'\n",
      "\n",
      "During handling of the above exception, another exception occurred:\n",
      "\n",
      "Traceback (most recent call last):\n",
      "  File \"D:\\anaconda\\lib\\site-packages\\IPython\\core\\ultratb.py\", line 1169, in get_records\n",
      "    return _fixed_getinnerframes(etb, number_of_lines_of_context, tb_offset)\n",
      "  File \"D:\\anaconda\\lib\\site-packages\\IPython\\core\\ultratb.py\", line 316, in wrapped\n",
      "    return f(*args, **kwargs)\n",
      "  File \"D:\\anaconda\\lib\\site-packages\\IPython\\core\\ultratb.py\", line 350, in _fixed_getinnerframes\n",
      "    records = fix_frame_records_filenames(inspect.getinnerframes(etb, context))\n",
      "  File \"D:\\anaconda\\lib\\inspect.py\", line 1502, in getinnerframes\n",
      "    frameinfo = (tb.tb_frame,) + getframeinfo(tb, context)\n",
      "  File \"D:\\anaconda\\lib\\inspect.py\", line 1460, in getframeinfo\n",
      "    filename = getsourcefile(frame) or getfile(frame)\n",
      "  File \"D:\\anaconda\\lib\\inspect.py\", line 696, in getsourcefile\n",
      "    if getattr(getmodule(object, filename), '__loader__', None) is not None:\n",
      "  File \"D:\\anaconda\\lib\\inspect.py\", line 733, in getmodule\n",
      "    if ismodule(module) and hasattr(module, '__file__'):\n",
      "  File \"D:\\anaconda\\lib\\site-packages\\tensorflow\\__init__.py\", line 50, in __getattr__\n",
      "    module = self._load()\n",
      "  File \"D:\\anaconda\\lib\\site-packages\\tensorflow\\__init__.py\", line 44, in _load\n",
      "    module = _importlib.import_module(self.__name__)\n",
      "  File \"D:\\anaconda\\lib\\importlib\\__init__.py\", line 127, in import_module\n",
      "    return _bootstrap._gcd_import(name[level:], package, level)\n",
      "  File \"<frozen importlib._bootstrap>\", line 1006, in _gcd_import\n",
      "  File \"<frozen importlib._bootstrap>\", line 983, in _find_and_load\n",
      "  File \"<frozen importlib._bootstrap>\", line 965, in _find_and_load_unlocked\n",
      "ModuleNotFoundError: No module named 'tensorflow_core.estimator'\n",
      "Traceback (most recent call last):\n",
      "  File \"D:\\anaconda\\lib\\site-packages\\IPython\\core\\interactiveshell.py\", line 3417, in run_code\n",
      "    exec(code_obj, self.user_global_ns, self.user_ns)\n",
      "  File \"<ipython-input-12-0d615eaf079a>\", line 1, in <module>\n",
      "    print(confusion_matrix(y_test,final_preds))\n",
      "NameError: name 'confusion_matrix' is not defined\n",
      "\n",
      "During handling of the above exception, another exception occurred:\n",
      "\n",
      "Traceback (most recent call last):\n",
      "  File \"D:\\anaconda\\lib\\site-packages\\IPython\\core\\interactiveshell.py\", line 2044, in showtraceback\n",
      "    stb = value._render_traceback_()\n",
      "AttributeError: 'NameError' object has no attribute '_render_traceback_'\n",
      "\n",
      "During handling of the above exception, another exception occurred:\n",
      "\n",
      "Traceback (most recent call last):\n",
      "  File \"D:\\anaconda\\lib\\site-packages\\IPython\\core\\interactiveshell.py\", line 3337, in run_ast_nodes\n",
      "    if (await self.run_code(code, result,  async_=asy)):\n",
      "  File \"D:\\anaconda\\lib\\site-packages\\IPython\\core\\interactiveshell.py\", line 3434, in run_code\n",
      "    self.showtraceback(running_compiled_code=True)\n",
      "  File \"D:\\anaconda\\lib\\site-packages\\IPython\\core\\interactiveshell.py\", line 2047, in showtraceback\n",
      "    value, tb, tb_offset=tb_offset)\n",
      "  File \"D:\\anaconda\\lib\\site-packages\\IPython\\core\\ultratb.py\", line 1436, in structured_traceback\n",
      "    self, etype, value, tb, tb_offset, number_of_lines_of_context)\n",
      "  File \"D:\\anaconda\\lib\\site-packages\\IPython\\core\\ultratb.py\", line 1336, in structured_traceback\n",
      "    self, etype, value, tb, tb_offset, number_of_lines_of_context\n",
      "  File \"D:\\anaconda\\lib\\site-packages\\IPython\\core\\ultratb.py\", line 1193, in structured_traceback\n",
      "    tb_offset)\n",
      "  File \"D:\\anaconda\\lib\\site-packages\\IPython\\core\\ultratb.py\", line 1150, in format_exception_as_a_whole\n",
      "    last_unique, recursion_repeat = find_recursion(orig_etype, evalue, records)\n",
      "  File \"D:\\anaconda\\lib\\site-packages\\IPython\\core\\ultratb.py\", line 451, in find_recursion\n",
      "    return len(records), 0\n",
      "TypeError: object of type 'NoneType' has no len()\n",
      "\n",
      "During handling of the above exception, another exception occurred:\n",
      "\n",
      "Traceback (most recent call last):\n",
      "  File \"D:\\anaconda\\lib\\site-packages\\IPython\\core\\interactiveshell.py\", line 2044, in showtraceback\n",
      "    stb = value._render_traceback_()\n",
      "AttributeError: 'TypeError' object has no attribute '_render_traceback_'\n",
      "\n",
      "During handling of the above exception, another exception occurred:\n",
      "\n",
      "Traceback (most recent call last):\n",
      "  File \"D:\\anaconda\\lib\\site-packages\\IPython\\core\\interactiveshell.py\", line 2922, in _run_cell\n",
      "    return runner(coro)\n",
      "  File \"D:\\anaconda\\lib\\site-packages\\IPython\\core\\async_helpers.py\", line 68, in _pseudo_sync_runner\n",
      "    coro.send(None)\n",
      "  File \"D:\\anaconda\\lib\\site-packages\\IPython\\core\\interactiveshell.py\", line 3146, in run_cell_async\n",
      "    interactivity=interactivity, compiler=compiler, result=result)\n",
      "  File \"D:\\anaconda\\lib\\site-packages\\IPython\\core\\interactiveshell.py\", line 3356, in run_ast_nodes\n",
      "    self.showtraceback()\n",
      "  File \"D:\\anaconda\\lib\\site-packages\\IPython\\core\\interactiveshell.py\", line 2047, in showtraceback\n",
      "    value, tb, tb_offset=tb_offset)\n",
      "  File \"D:\\anaconda\\lib\\site-packages\\IPython\\core\\ultratb.py\", line 1436, in structured_traceback\n",
      "    self, etype, value, tb, tb_offset, number_of_lines_of_context)\n",
      "  File \"D:\\anaconda\\lib\\site-packages\\IPython\\core\\ultratb.py\", line 1336, in structured_traceback\n",
      "    self, etype, value, tb, tb_offset, number_of_lines_of_context\n",
      "  File \"D:\\anaconda\\lib\\site-packages\\IPython\\core\\ultratb.py\", line 1211, in structured_traceback\n",
      "    chained_exceptions_tb_offset)\n",
      "  File \"D:\\anaconda\\lib\\site-packages\\IPython\\core\\ultratb.py\", line 1150, in format_exception_as_a_whole\n",
      "    last_unique, recursion_repeat = find_recursion(orig_etype, evalue, records)\n",
      "  File \"D:\\anaconda\\lib\\site-packages\\IPython\\core\\ultratb.py\", line 451, in find_recursion\n",
      "    return len(records), 0\n",
      "TypeError: object of type 'NoneType' has no len()\n",
      "\n",
      "During handling of the above exception, another exception occurred:\n",
      "\n",
      "Traceback (most recent call last):\n",
      "  File \"D:\\anaconda\\lib\\site-packages\\IPython\\core\\interactiveshell.py\", line 2044, in showtraceback\n",
      "    stb = value._render_traceback_()\n",
      "AttributeError: 'TypeError' object has no attribute '_render_traceback_'\n",
      "\n",
      "During handling of the above exception, another exception occurred:\n",
      "\n",
      "Traceback (most recent call last):\n",
      "  File \"D:\\anaconda\\lib\\site-packages\\IPython\\core\\ultratb.py\", line 1169, in get_records\n",
      "    return _fixed_getinnerframes(etb, number_of_lines_of_context, tb_offset)\n",
      "  File \"D:\\anaconda\\lib\\site-packages\\IPython\\core\\ultratb.py\", line 316, in wrapped\n",
      "    return f(*args, **kwargs)\n",
      "  File \"D:\\anaconda\\lib\\site-packages\\IPython\\core\\ultratb.py\", line 350, in _fixed_getinnerframes\n",
      "    records = fix_frame_records_filenames(inspect.getinnerframes(etb, context))\n",
      "  File \"D:\\anaconda\\lib\\inspect.py\", line 1502, in getinnerframes\n",
      "    frameinfo = (tb.tb_frame,) + getframeinfo(tb, context)\n",
      "  File \"D:\\anaconda\\lib\\inspect.py\", line 1460, in getframeinfo\n",
      "    filename = getsourcefile(frame) or getfile(frame)\n",
      "  File \"D:\\anaconda\\lib\\inspect.py\", line 696, in getsourcefile\n",
      "    if getattr(getmodule(object, filename), '__loader__', None) is not None:\n",
      "  File \"D:\\anaconda\\lib\\inspect.py\", line 733, in getmodule\n",
      "    if ismodule(module) and hasattr(module, '__file__'):\n",
      "  File \"D:\\anaconda\\lib\\site-packages\\tensorflow\\__init__.py\", line 50, in __getattr__\n",
      "    module = self._load()\n",
      "  File \"D:\\anaconda\\lib\\site-packages\\tensorflow\\__init__.py\", line 44, in _load\n",
      "    module = _importlib.import_module(self.__name__)\n",
      "  File \"D:\\anaconda\\lib\\importlib\\__init__.py\", line 127, in import_module\n",
      "    return _bootstrap._gcd_import(name[level:], package, level)\n",
      "  File \"<frozen importlib._bootstrap>\", line 1006, in _gcd_import\n",
      "  File \"<frozen importlib._bootstrap>\", line 983, in _find_and_load\n",
      "  File \"<frozen importlib._bootstrap>\", line 965, in _find_and_load_unlocked\n",
      "ModuleNotFoundError: No module named 'tensorflow_core.estimator'\n"
     ]
    }
   ],
   "source": [
    "print(confusion_matrix(y_test,final_preds))"
   ]
  },
  {
   "cell_type": "code",
   "execution_count": null,
   "metadata": {},
   "outputs": [],
   "source": []
  },
  {
   "cell_type": "code",
   "execution_count": 21,
   "metadata": {
    "scrolled": true
   },
   "outputs": [
    {
     "name": "stdout",
     "output_type": "stream",
     "text": [
      "             precision    recall  f1-score   support\n",
      "\n",
      "          0       1.00      1.00      1.00        20\n",
      "          1       1.00      1.00      1.00         6\n",
      "          2       1.00      1.00      1.00        19\n",
      "\n",
      "avg / total       1.00      1.00      1.00        45\n",
      "\n"
     ]
    }
   ],
   "source": [
    "print(classification_report(y_test,final_preds))"
   ]
  },
  {
   "cell_type": "markdown",
   "metadata": {},
   "source": [
    "# Great Job!"
   ]
  }
 ],
 "metadata": {
  "kernelspec": {
   "display_name": "Python 3",
   "language": "python",
   "name": "python3"
  },
  "language_info": {
   "codemirror_mode": {
    "name": "ipython",
    "version": 3
   },
   "file_extension": ".py",
   "mimetype": "text/x-python",
   "name": "python",
   "nbconvert_exporter": "python",
   "pygments_lexer": "ipython3",
   "version": "3.7.4"
  }
 },
 "nbformat": 4,
 "nbformat_minor": 1
}
